21/06/22 04:25:38 3241.140451918550848 DEBUG utils.debug_sql (0.000) SELECT @@SQL_AUTO_IS_NULL; args=None
21/06/22 04:25:38 3241.140451918550848 DEBUG utils.debug_sql (0.000) SET SESSION TRANSACTION ISOLATION LEVEL READ COMMITTED; args=None
21/06/22 04:25:38 3241.140451918550848 DEBUG utils.debug_sql (0.001) SHOW FULL TABLES; args=None
21/06/22 04:25:38 3241.140451918550848 DEBUG utils.debug_sql (0.001) SELECT `django_migrations`.`id`, `django_migrations`.`app`, `django_migrations`.`name`, `django_migrations`.`applied` FROM `django_migrations`; args=()
Traceback (most recent call last):
  File "manage.py", line 22, in <module>
    execute_from_command_line(sys.argv)
  File "/usr/local/lib/python3.6/dist-packages/django/core/management/__init__.py", line 401, in execute_from_command_line
    utility.execute()
  File "/usr/local/lib/python3.6/dist-packages/django/core/management/__init__.py", line 395, in execute
    self.fetch_command(subcommand).run_from_argv(self.argv)
  File "/usr/local/lib/python3.6/dist-packages/django/core/management/base.py", line 330, in run_from_argv
    self.execute(*args, **cmd_options)
  File "/usr/local/lib/python3.6/dist-packages/django/core/management/base.py", line 371, in execute
    output = self.handle(*args, **options)
  File "/usr/local/lib/python3.6/dist-packages/django_extensions/management/utils.py", line 62, in inner
    ret = func(self, *args, **kwargs)
  File "/usr/local/lib/python3.6/dist-packages/django_extensions/management/commands/runserver_plus.py", line 290, in handle
    self.inner_run(options)
  File "/usr/local/lib/python3.6/dist-packages/django_extensions/management/commands/runserver_plus.py", line 416, in inner_run
    ssl_context=ssl_context,
  File "/usr/local/lib/python3.6/dist-packages/werkzeug/serving.py", line 1030, in run_simple
    s.bind(server_address)
OSError: [Errno 98] Address already in use
