Error occurred during checks: OperationalError(2003, "Can't connect to MySQL server on '127.0.0.1' (111)")

 * Running on https://0.0.0.0:8000/ (Press CTRL+C to quit)

 * Restarting with stat

te_from_command_line(sys.argv)
  File "/usr/local/lib/python3.6/dist-packages/django/core/management/__init__.py", line 401, in execute_from_command_line
    utility.execute()
  File "/usr/local/lib/python3.6/dist-packages/django/core/management/__init__.py", line 395, in execute
    self.fetch_command(subcommand).run_from_argv(self.argv)
  File "/usr/local/lib/python3.6/dist-packages/django/core/management/base.py", line 330, in run_from_argv
    self.execute(*args, **cmd_options)
  File "/usr/local/lib/python3.6/dist-packages/django/core/management/base.py", line 371, in execute
    output = self.handle(*args, **options)
  File "/usr/local/lib/python3.6/dist-packages/django_extensions/management/utils.py", line 62, in inner
    ret = func(self, *args, **kwargs)
  File "/usr/local/lib/python3.6/dist-packages/django_extensions/management/commands/runserver_plus.py", line 290, in handle
    self.inner_run(options)
  File "/usr/local/lib/python3.6/dist-packages/django_extensions/management/commands/runserver_plus.py", line 416, in inner_run
    ssl_context=ssl_context,
  File "/usr/local/lib/python3.6/dist-packages/werkzeug/serving.py", line 1030, in run_simple
    s.bind(server_address)
OSError: [Errno 98] Address already in use
